Workbook
Name lstLocation: #REF!
Name lstOwnerAM: #REF!
Name lstOwnerComm: #REF!
Name lstStatus: #REF!
Name lstType: #REF!

Sheet 🏠 HOME
B2: FROM · PRICE LIST TRACKER
B3: ="Real estate development portfolio · Last Updated 28 june 2026" -> Real estate development portfolio · Last Updated 28 june 2026
B5: QUICK NAVIGATION
B7: VILAMOURA · 13 projects
B8: ▸ Nobilus | F8: ▸ Natura Village 4 | J8: ▸ Natura Village 7 | N8: ▸ Natura Village 9
B9: ▸ The Nine | F9: ▸ Terracota | J9: ▸ Rivus | N9: ▸ Fairways
B10: ▸ Estalagem das Cegonhas | F10: ▸ Springs - At the Els | J10: ▸ Zestia | N10: ▸ The Uncommon
B11: ▸ Botanica
B13: ALGARVE · 4 projects
B14: ▸ Sutaya | F14: ▸ Azuya | J14: ▸ Palmares | N14: ▸ Monte Rei
B16: LISBON & NORTH · 2 projects
B17: ▸ Aroeira Collections | F17: ▸ Vale Pisão Grand Park

Sheet Overview
B2: Portfolio Overview | H2: SELECT REGION → | I2: All regions | L2: {="Showing "&SUMPRODUCT((($I$2="All regions")+($X$7:$X$23=$I$2)>0)*(($I$4="All statuses")+($Y$7:$Y$23=$I$4)>0))&" of "&COUNTA($B$7:$B$23)} -> Showing 17 of 17 | Q2: Selected Project Status | R2: Units
B4: =COUNTA($B$7:$B$23)&" developments · one curation" -> 17 developments · one curation | H4: SELECT STATUS → | I4: All statuses | L4: developments match your filters | Q4: Available | R4: =E34 -> 15 | AA4: All regions | AC4: All statuses
Q5: Reserved | R5: =G34 -> 5
B6: Project | C6: Status | D6: Location | E6: Type | F6: Conclusion | G6: Units | H6: Available | I6: Pre-Reserved & Reserved | J6: PSPA | K6: Deeded | L6: Other | M6: % Sold | N6: GDV Asking (€M) | O6: Deeded Value (€M) | Q6: Under Contract | R6: =I34 -> 0 | X6: Region | Y6: Sales Status | AA6: Vilamoura | AC6: Active
B7: Natura Village | C7: =IFERROR(TRIM(_xlfn.XLOOKUP($B7,DATABASE_Table[Development],DATABASE_Table[Selling Status],"—")),"—") -> DEED | D7: {=IFERROR(INDEX(_xlfn._xlws.FILTER(DATABASE_Table[Location],(DATABASE_Table[Development]=$B7)*(DATABASE_Table[Location]<>"")),1),IFERROR(_xlfn.XLOOKUP($B7,DATABASE_Table[Development],DATABASE_Table[Local],"—"),"—"))} -> Vilamoura, Algarve | E7: {=IFERROR(INDEX(_xlfn._xlws.FILTER(DATABASE_Table[Typology],(DATABASE_Table[Development]=$B7)*(DATABASE_Table[Typology]<>"")),1),"—")} -> V3 | F7: {=IFERROR(INDEX(_xlfn._xlws.FILTER(DATABASE_Table[Delivery Expected],(DATABASE_Table[Development]=$B7)*(DATABASE_Table[Delivery Expected]<>"")),1),"—")} -> — | G7: =COUNTIF(DATABASE_Table[Development],$B7) -> 38 | H7: {=SUMPRODUCT((DATABASE_Table[Development]=$B7)*(TRIM(DATABASE_Table[Selling Status])="AVAILABLE"))} -> 8 | I7: {=SUMPRODUCT((DATABASE_Table[Development]=$B7)*((TRIM(DATABASE_Table[Selling Status])="RESERVED")+(TRIM(DATABASE_Table[Selling Status])="PRE-RESERVED")))} -> 4 | J7: {=SUMPRODUCT((DATABASE_Table[Development]=$B7)*(LEFT(TRIM(DATABASE_Table[Selling Status]),4)="PSPA"))} -> 3 | K7: {=SUMPRODUCT((DATABASE_Table[Development]=$B7)*(TRIM(DATABASE_Table[Selling Status])="DEED"))} -> 23 | L7: {=SUMPRODUCT((DATABASE_Table[Development]=$B7)*((TRIM(DATABASE_Table[Selling Status])="NOT FOR SALE")+(LEFT(TRIM(DATABASE_Table[Selling Status]),4)="UPON")))} -> 0 | M7: =IFERROR((I7+J7+K7)/(G7-L7),0) -> 0.78947368 | N7: =SUMIF(DATABASE_Table[Development],$B7,DATABASE_Table[Current Asking price( Total)])/1000000 -> 37.7745 | O7: {=SUMPRODUCT((DATABASE_Table[Development]=$B7)*(TRIM(DATABASE_Table[Selling Status])="DEED SIGNED")*DATABASE_Table[Sell price (RE Asset)])/1000000} -> 0 | Q7: Deeded | R7: =K34 -> 0 | X7: {=IFERROR(_xlfn.SWITCH(_xlfn.XLOOKUP($B7,DATABASE_Table[Development],DATABASE_Table[Local],"Center"),"Vilamoura","Vilamoura","Algarve","Algarve","North","North","Center"),"Center")} -> Vilamoura | Y7: {=_xlfn.IFS(G7=0,"—",M7>=0.999,"Sold Out",(I7+J7+K7)=0,"Coming Soon",TRUE,"Active")} -> Active | AA7: Algarve | AC7: Sold Out
B8: The Nine | C8: =IFERROR(TRIM(_xlfn.XLOOKUP($B8,DATABASE_Table[Development],DATABASE_Table[Selling Status],"—")),"—") -> DEED | D8: {=IFERROR(INDEX(_xlfn._xlws.FILTER(DATABASE_Table[Location],(DATABASE_Table[Development]=$B8)*(DATABASE_Table[Location]<>"")),1),IFERROR(_xlfn.XLOOKUP($B8,DATABASE_Table[Development],DATABASE_Table[Local],"—"),"—"))} -> Vilamoura, Algarve | E8: {=IFERROR(INDEX(_xlfn._xlws.FILTER(DATABASE_Table[Typology],(DATABASE_Table[Development]=$B8)*(DATABASE_Table[Typology]<>"")),1),"—")} -> T3 | F8: {=IFERROR(INDEX(_xlfn._xlws.FILTER(DATABASE_Table[Delivery Expected],(DATABASE_Table[Development]=$B8)*(DATABASE_Table[Delivery Expected]<>"")),1),"—")} -> — | G8: =COUNTIF(DATABASE_Table[Development],$B8) -> 48 | H8: {=SUMPRODUCT((DATABASE_Table[Development]=$B8)*(TRIM(DATABASE_Table[Selling Status])="AVAILABLE"))} -> 0 | I8: {=SUMPRODUCT((DATABASE_Table[Development]=$B8)*((TRIM(DATABASE_Table[Selling Status])="RESERVED")+(TRIM(DATABASE_Table[Selling Status])="PRE-RESERVED")))} -> 0 | J8: {=SUMPRODUCT((DATABASE_Table[Development]=$B8)*(LEFT(TRIM(DATABASE_Table[Selling Status]),4)="PSPA"))} -> 0 | K8: {=SUMPRODUCT((DATABASE_Table[Development]=$B8)*(TRIM(DATABASE_Table[Selling Status])="DEED"))} -> 48 | L8: {=SUMPRODUCT((DATABASE_Table[Development]=$B8)*((TRIM(DATABASE_Table[Selling Status])="NOT FOR SALE")+(LEFT(TRIM(DATABASE_Table[Selling Status]),4)="UPON")))} -> 0 | M8: =IFERROR((I8+J8+K8)/(G8-L8),0) -> 1 | N8: =SUMIF(DATABASE_Table[Development],$B8,DATABASE_Table[Current Asking price( Total)])/1000000 -> 32.79 | O8: {=SUMPRODUCT((DATABASE_Table[Development]=$B8)*(TRIM(DATABASE_Table[Selling Status])="DEED SIGNED")*DATABASE_Table[Sell price (RE Asset)])/1000000} -> 0 | Q8: Other | R8: =_xlfn.XLOOKUP($E$31,$B$7:$B$23,$L$7:$L$23,0) -> 25 | X8: {=IFERROR(_xlfn.SWITCH(_xlfn.XLOOKUP($B8,DATABASE_Table[Development],DATABASE_Table[Local],"Center"),"Vilamoura","Vilamoura","Algarve","Algarve","North","North","Center"),"Center")} -> Vilamoura | Y8: {=_xlfn.IFS(G8=0,"—",M8>=0.999,"Sold Out",(I8+J8+K8)=0,"Coming Soon",TRUE,"Active")} -> Sold Out | AA8: Center | AC8: Coming Soon
B9: MOURAGOLFE | C9: =IFERROR(TRIM(_xlfn.XLOOKUP($B9,DATABASE_Table[Development],DATABASE_Table[Selling Status],"—")),"—") -> DEED | D9: {=IFERROR(INDEX(_xlfn._xlws.FILTER(DATABASE_Table[Location],(DATABASE_Table[Development]=$B9)*(DATABASE_Table[Location]<>"")),1),IFERROR(_xlfn.XLOOKUP($B9,DATABASE_Table[Development],DATABASE_Table[Local],"—"),"—"))} -> Vilamoura | E9: {=IFERROR(INDEX(_xlfn._xlws.FILTER(DATABASE_Table[Typology],(DATABASE_Table[Development]=$B9)*(DATABASE_Table[Typology]<>"")),1),"—")} -> Plot | F9: {=IFERROR(INDEX(_xlfn._xlws.FILTER(DATABASE_Table[Delivery Expected],(DATABASE_Table[Development]=$B9)*(DATABASE_Table[Delivery Expected]<>"")),1),"—")} -> — | G9: =COUNTIF(DATABASE_Table[Development],$B9) -> 13 | H9: {=SUMPRODUCT((DATABASE_Table[Development]=$B9)*(TRIM(DATABASE_Table[Selling Status])="AVAILABLE"))} -> 0 | I9: {=SUMPRODUCT((DATABASE_Table[Development]=$B9)*((TRIM(DATABASE_Table[Selling Status])="RESERVED")+(TRIM(DATABASE_Table[Selling Status])="PRE-RESERVED")))} -> 0 | J9: {=SUMPRODUCT((DATABASE_Table[Development]=$B9)*(LEFT(TRIM(DATABASE_Table[Selling Status]),4)="PSPA"))} -> 1 | K9: {=SUMPRODUCT((DATABASE_Table[Development]=$B9)*(TRIM(DATABASE_Table[Selling Status])="DEED"))} -> 12 | L9: {=SUMPRODUCT((DATABASE_Table[Development]=$B9)*((TRIM(DATABASE_Table[Selling Status])="NOT FOR SALE")+(LEFT(TRIM(DATABASE_Table[Selling Status]),4)="UPON")))} -> 0 | M9: =IFERROR((I9+J9+K9)/(G9-L9),0) -> 1 | N9: =SUMIF(DATABASE_Table[Development],$B9,DATABASE_Table[Current Asking price( Total)])/1000000 -> 8.665 | O9: {=SUMPRODUCT((DATABASE_Table[Development]=$B9)*(TRIM(DATABASE_Table[Selling Status])="DEED SIGNED")*DATABASE_Table[Sell price (RE Asset)])/1000000} -> 0 | X9: {=IFERROR(_xlfn.SWITCH(_xlfn.XLOOKUP($B9,DATABASE_Table[Development],DATABASE_Table[Local],"Center"),"Vilamoura","Vilamoura","Algarve","Algarve","North","North","Center"),"Center")} -> Vilamoura | Y9: {=_xlfn.IFS(G9=0,"—",M9>=0.999,"Sold Out",(I9+J9+K9)=0,"Coming Soon",TRUE,"Active")} -> Sold Out | AA9: North
B10: Terracota | C10: =IFERROR(TRIM(_xlfn.XLOOKUP($B10,DATABASE_Table[Development],DATABASE_Table[Selling Status],"—")),"—") -> PSPA | D10: {=IFERROR(INDEX(_xlfn._xlws.FILTER(DATABASE_Table[Location],(DATABASE_Table[Development]=$B10)*(DATABASE_Table[Location]<>"")),1),IFERROR(_xlfn.XLOOKUP($B10,DATABASE_Table[Development],DATABASE_Table[Local],"—"),"—"))} -> Vilamoura, Algarve | E10: {=IFERROR(INDEX(_xlfn._xlws.FILTER(DATABASE_Table[Typology],(DATABASE_Table[Development]=$B10)*(DATABASE_Table[Typology]<>"")),1),"—")} -> T3 | F10: {=IFERROR(INDEX(_xlfn._xlws.FILTER(DATABASE_Table[Delivery Expected],(DATABASE_Table[Development]=$B10)*(DATABASE_Table[Delivery Expected]<>"")),1),"—")} -> — | G10: =COUNTIF(DATABASE_Table[Development],$B10) -> 87 | H10: {=SUMPRODUCT((DATABASE_Table[Development]=$B10)*(TRIM(DATABASE_Table[Selling Status])="AVAILABLE"))} -> 12 | I10: {=SUMPRODUCT((DATABASE_Table[Development]=$B10)*((TRIM(DATABASE_Table[Selling Status])="RESERVED")+(TRIM(DATABASE_Table[Selling Status])="PRE-RESERVED")))} -> 3 | J10: {=SUMPRODUCT((DATABASE_Table[Development]=$B10)*(LEFT(TRIM(DATABASE_Table[Selling Status]),4)="PSPA"))} -> 72 | K10: {=SUMPRODUCT((DATABASE_Table[Development]=$B10)*(TRIM(DATABASE_Table[Selling Status])="DEED"))} -> 0 | L10: {=SUMPRODUCT((DATABASE_Table[Development]=$B10)*((TRIM(DATABASE_Table[Selling Status])="NOT FOR SALE")+(LEFT(TRIM(DATABASE_Table[Selling Status]),4)="UPON")))} -> 0 | M10: =IFERROR((I10+J10+K10)/(G10-L10),0) -> 0.86206897 | N10: =SUMIF(DATABASE_Table[Development],$B10,DATABASE_Table[Current Asking price( Total)])/1000000 -> 52.35185 | O10: {=SUMPRODUCT((DATABASE_Table[Development]=$B10)*(TRIM(DATABASE_Table[Selling Status])="DEED SIGNED")*DATABASE_Table[Sell price (RE Asset)])/1000000} -> 0 | X10: {=IFERROR(_xlfn.SWITCH(_xlfn.XLOOKUP($B10,DATABASE_Table[Development],DATABASE_Table[Local],"Center"),"Vilamoura","Vilamoura","Algarve","Algarve","North","North","Center"),"Center")} -> Vilamoura | Y10: {=_xlfn.IFS(G10=0,"—",M10>=0.999,"Sold Out",(I10+J10+K10)=0,"Coming Soon",TRUE,"Active")} -> Active
B11: Nobilus | C11: =IFERROR(TRIM(_xlfn.XLOOKUP($B11,DATABASE_Table[Development],DATABASE_Table[Selling Status],"—")),"—") -> PSPA | D11: {=IFERROR(INDEX(_xlfn._xlws.FILTER(DATABASE_Table[Location],(DATABASE_Table[Development]=$B11)*(DATABASE_Table[Location]<>"")),1),IFERROR(_xlfn.XLOOKUP($B11,DATABASE_Table[Development],DATABASE_Table[Local],"—"),"—"))} -> Vilamoura, Algarve | E11: {=IFERROR(INDEX(_xlfn._xlws.FILTER(DATABASE_Table[Typology],(DATABASE_Table[Development]=$B11)*(DATABASE_Table[Typology]<>"")),1),"—")} -> T2 | F11: {=IFERROR(INDEX(_xlfn._xlws.FILTER(DATABASE_Table[Delivery Expected],(DATABASE_Table[Development]=$B11)*(DATABASE_Table[Delivery Expected]<>"")),1),"—")} -> — | G11: =COUNTIF(DATABASE_Table[Development],$B11) -> 47 | H11: {=SUMPRODUCT((DATABASE_Table[Development]=$B11)*(TRIM(DATABASE_Table[Selling Status])="AVAILABLE"))} -> 33 | I11: {=SUMPRODUCT((DATABASE_Table[Development]=$B11)*((TRIM(DATABASE_Table[Selling Status])="RESERVED")+(TRIM(DATABASE_Table[Selling Status])="PRE-RESERVED")))} -> 0 | J11: {=SUMPRODUCT((DATABASE_Table[Development]=$B11)*(LEFT(TRIM(DATABASE_Table[Selling Status]),4)="PSPA"))} -> 14 | K11: {=SUMPRODUCT((DATABASE_Table[Development]=$B11)*(TRIM(DATABASE_Table[Selling Status])="DEED"))} -> 0 | L11: {=SUMPRODUCT((DATABASE_Table[Development]=$B11)*((TRIM(DATABASE_Table[Selling Status])="NOT FOR SALE")+(LEFT(TRIM(DATABASE_Table[Selling Status]),4)="UPON")))} -> 0 | M11: =IFERROR((I11+J11+K11)/(G11-L11),0) -> 0.29787234 | N11: =SUMIF(DATABASE_Table[Development],$B11,DATABASE_Table[Current Asking price( Total)])/1000000 -> 45.4265 | O11: {=SUMPRODUCT((DATABASE_Table[Development]=$B11)*(TRIM(DATABASE_Table[Selling Status])="DEED SIGNED")*DATABASE_Table[Sell price (RE Asset)])/1000000} -> 0 | Q11: Comparison | R11: % Sold | U11: Comparison | V11: GDV (€M) | X11: {=IFERROR(_xlfn.SWITCH(_xlfn.XLOOKUP($B11,DATABASE_Table[Development],DATABASE_Table[Local],"Center"),"Vilamoura","Vilamoura","Algarve","Algarve","North","North","Center"),"Center")} -> Vilamoura | Y11: {=_xlfn.IFS(G11=0,"—",M11>=0.999,"Sold Out",(I11+J11+K11)=0,"Coming Soon",TRUE,"Active")} -> Active
B12: Zestia | C12: =IFERROR(TRIM(_xlfn.XLOOKUP($B12,DATABASE_Table[Development],DATABASE_Table[Selling Status],"—")),"—") -> AVAILABLE | D12: {=IFERROR(INDEX(_xlfn._xlws.FILTER(DATABASE_Table[Location],(DATABASE_Table[Development]=$B12)*(DATABASE_Table[Location]<>"")),1),IFERROR(_xlfn.XLOOKUP($B12,DATABASE_Table[Development],DATABASE_Table[Local],"—"),"—"))} -> Vilamoura, Algarve | E12: {=IFERROR(INDEX(_xlfn._xlws.FILTER(DATABASE_Table[Typology],(DATABASE_Table[Development]=$B12)*(DATABASE_Table[Typology]<>"")),1),"—")} -> T2 | F12: {=IFERROR(INDEX(_xlfn._xlws.FILTER(DATABASE_Table[Delivery Expected],(DATABASE_Table[Development]=$B12)*(DATABASE_Table[Delivery Expected]<>"")),1),"—")} -> — | G12: =COUNTIF(DATABASE_Table[Development],$B12) -> 62 | H12: {=SUMPRODUCT((DATABASE_Table[Development]=$B12)*(TRIM(DATABASE_Table[Selling Status])="AVAILABLE"))} -> 55 | I12: {=SUMPRODUCT((DATABASE_Table[Development]=$B12)*((TRIM(DATABASE_Table[Selling Status])="RESERVED")+(TRIM(DATABASE_Table[Selling Status])="PRE-RESERVED")))} -> 0 | J12: {=SUMPRODUCT((DATABASE_Table[Development]=$B12)*(LEFT(TRIM(DATABASE_Table[Selling Status]),4)="PSPA"))} -> 7 | K12: {=SUMPRODUCT((DATABASE_Table[Development]=$B12)*(TRIM(DATABASE_Table[Selling Status])="DEED"))} -> 0 | L12: {=SUMPRODUCT((DATABASE_Table[Development]=$B12)*((TRIM(DATABASE_Table[Selling Status])="NOT FOR SALE")+(LEFT(TRIM(DATABASE_Table[Selling Status]),4)="UPON")))} -> 0 | M12: =IFERROR((I12+J12+K12)/(G12-L12),0) -> 0.11290323 | N12: =SUMIF(DATABASE_Table[Development],$B12,DATABASE_Table[Current Asking price( Total)])/1000000 -> 54.5 | O12: {=SUMPRODUCT((DATABASE_Table[Development]=$B12)*(TRIM(DATABASE_Table[Selling Status])="DEED SIGNED")*DATABASE_Table[Sell price (RE Asset)])/1000000} -> 0 | Q12: =$E$31 -> Vale Pisão Grand Park | R12: =M34 -> 0.25 | U12: =$E$31 -> Vale Pisão Grand Park | V12: =N34 -> 37.42 | X12: {=IFERROR(_xlfn.SWITCH(_xlfn.XLOOKUP($B12,DATABASE_Table[Development],DATABASE_Table[Local],"Center"),"Vilamoura","Vilamoura","Algarve","Algarve","North","North","Center"),"Center")} -> Vilamoura | Y12: {=_xlfn.IFS(G12=0,"—",M12>=0.999,"Sold Out",(I12+J12+K12)=0,"Coming Soon",TRUE,"Active")} -> Active
B13: VM PARQUE | C13: =IFERROR(TRIM(_xlfn.XLOOKUP($B13,DATABASE_Table[Development],DATABASE_Table[Selling Status],"—")),"—") -> DEED | D13: {=IFERROR(INDEX(_xlfn._xlws.FILTER(DATABASE_Table[Location],(DATABASE_Table[Development]=$B13)*(DATABASE_Table[Location]<>"")),1),IFERROR(_xlfn.XLOOKUP($B13,DATABASE_Table[Development],DATABASE_Table[Local],"—"),"—"))} -> Vilamoura | E13: {=IFERROR(INDEX(_xlfn._xlws.FILTER(DATABASE_Table[Typology],(DATABASE_Table[Development]=$B13)*(DATABASE_Table[Typology]<>"")),1),"—")} -> V2 | F13: {=IFERROR(INDEX(_xlfn._xlws.FILTER(DATABASE_Table[Delivery Expected],(DATABASE_Table[Development]=$B13)*(DATABASE_Table[Delivery Expected]<>"")),1),"—")} -> — | G13: =COUNTIF(DATABASE_Table[Development],$B13) -> 40 | H13: {=SUMPRODUCT((DATABASE_Table[Development]=$B13)*(TRIM(DATABASE_Table[Selling Status])="AVAILABLE"))} -> 0 | I13: {=SUMPRODUCT((DATABASE_Table[Development]=$B13)*((TRIM(DATABASE_Table[Selling Status])="RESERVED")+(TRIM(DATABASE_Table[Selling Status])="PRE-RESERVED")))} -> 0 | J13: {=SUMPRODUCT((DATABASE_Table[Development]=$B13)*(LEFT(TRIM(DATABASE_Table[Selling Status]),4)="PSPA"))} -> 0 | K13: {=SUMPRODUCT((DATABASE_Table[Development]=$B13)*(TRIM(DATABASE_Table[Selling Status])="DEED"))} -> 40 | L13: {=SUMPRODUCT((DATABASE_Table[Development]=$B13)*((TRIM(DATABASE_Table[Selling Status])="NOT FOR SALE")+(LEFT(TRIM(DATABASE_Table[Selling Status]),4)="UPON")))} -> 0 | M13: =IFERROR((I13+J13+K13)/(G13-L13),0) -> 1 | N13: =SUMIF(DATABASE_Table[Development],$B13,DATABASE_Table[Current Asking price( Total)])/1000000 -> 43.05197 | O13: {=SUMPRODUCT((DATABASE_Table[Development]=$B13)*(TRIM(DATABASE_Table[Selling Status])="DEED SIGNED")*DATABASE_Table[Sell price (RE Asset)])/1000000} -> 0 | Q13: =_xlfn.XLOOKUP($E$31,$B$7:$B$23,$X$7:$X$23)&" Avg" -> North Avg | R13: =IFERROR(AVERAGEIF($X$7:$X$23,_xlfn.XLOOKUP($E$31,$B$7:$B$23,$X$7:$X$23),$M$7:$M$23),0) -> 0.25 | U13: =_xlfn.XLOOKUP($E$31,$B$7:$B$23,$X$7:$X$23)&" Avg" -> North Avg | V13: =IFERROR(AVERAGEIF($X$7:$X$23,_xlfn.XLOOKUP($E$31,$B$7:$B$23,$X$7:$X$23),$N$7:$N$23),0) -> 37.42 | X13: {=IFERROR(_xlfn.SWITCH(_xlfn.XLOOKUP($B13,DATABASE_Table[Development],DATABASE_Table[Local],"Center"),"Vilamoura","Vilamoura","Algarve","Algarve","North","North","Center"),"Center")} -> Vilamoura | Y13: {=_xlfn.IFS(G13=0,"—",M13>=0.999,"Sold Out",(I13+J13+K13)=0,"Coming Soon",TRUE,"Active")} -> Sold Out
B14: Springs - At the Els | C14: =IFERROR(TRIM(_xlfn.XLOOKUP($B14,DATABASE_Table[Development],DATABASE_Table[Selling Status],"—")),"—") -> AVAILABLE | D14: {=IFERROR(INDEX(_xlfn._xlws.FILTER(DATABASE_Table[Location],(DATABASE_Table[Development]=$B14)*(DATABASE_Table[Location]<>"")),1),IFERROR(_xlfn.XLOOKUP($B14,DATABASE_Table[Development],DATABASE_Table[Local],"—"),"—"))} -> Vilamoura, Algarve | E14: {=IFERROR(INDEX(_xlfn._xlws.FILTER(DATABASE_Table[Typology],(DATABASE_Table[Development]=$B14)*(DATABASE_Table[Typology]<>"")),1),"—")} -> Plot | F14: {=IFERROR(INDEX(_xlfn._xlws.FILTER(DATABASE_Table[Delivery Expected],(DATABASE_Table[Development]=$B14)*(DATABASE_Table[Delivery Expected]<>"")),1),"—")} -> — | G14: =COUNTIF(DATABASE_Table[Development],$B14) -> 101 | H14: {=SUMPRODUCT((DATABASE_Table[Development]=$B14)*(TRIM(DATABASE_Table[Selling Status])="AVAILABLE"))} -> 92 | I14: {=SUMPRODUCT((DATABASE_Table[Development]=$B14)*((TRIM(DATABASE_Table[Selling Status])="RESERVED")+(TRIM(DATABASE_Table[Selling Status])="PRE-RESERVED")))} -> 3 | J14: {=SUMPRODUCT((DATABASE_Table[Development]=$B14)*(LEFT(TRIM(DATABASE_Table[Selling Status]),4)="PSPA"))} -> 6 | K14: {=SUMPRODUCT((DATABASE_Table[Development]=$B14)*(TRIM(DATABASE_Table[Selling Status])="DEED"))} -> 0 | L14: {=SUMPRODUCT((DATABASE_Table[Development]=$B14)*((TRIM(DATABASE_Table[Selling Status])="NOT FOR SALE")+(LEFT(TRIM(DATABASE_Table[Selling Status]),4)="UPON")))} -> 0 | M14: =IFERROR((I14+J14+K14)/(G14-L14),0) -> 0.089108911 | N14: =SUMIF(DATABASE_Table[Development],$B14,DATABASE_Table[Current Asking price( Total)])/1000000 -> 183.77 | O14: {=SUMPRODUCT((DATABASE_Table[Development]=$B14)*(TRIM(DATABASE_Table[Selling Status])="DEED SIGNED")*DATABASE_Table[Sell price (RE Asset)])/1000000} -> 0 | Q14: Portfolio Avg | R14: =$M$24 -> 0.36222628 | U14: Portfolio Avg | V14: =AVERAGE($N$7:$N$23) -> 77.328269 | X14: {=IFERROR(_xlfn.SWITCH(_xlfn.XLOOKUP($B14,DATABASE_Table[Development],DATABASE_Table[Local],"Center"),"Vilamoura","Vilamoura","Algarve","Algarve","North","North","Center"),"Center")} -> Vilamoura | Y14: {=_xlfn.IFS(G14=0,"—",M14>=0.999,"Sold Out",(I14+J14+K14)=0,"Coming Soon",TRUE,"Active")} -> Active
B15: Botanica | C15: =IFERROR(TRIM(_xlfn.XLOOKUP($B15,DATABASE_Table[Development],DATABASE_Table[Selling Status],"—")),"—") -> RESERVED | D15: {=IFERROR(INDEX(_xlfn._xlws.FILTER(DATABASE_Table[Location],(DATABASE_Table[Development]=$B15)*(DATABASE_Table[Location]<>"")),1),IFERROR(_xlfn.XLOOKUP($B15,DATABASE_Table[Development],DATABASE_Table[Local],"—"),"—"))} -> Vilamoura, Algarve | E15: {=IFERROR(INDEX(_xlfn._xlws.FILTER(DATABASE_Table[Typology],(DATABASE_Table[Development]=$B15)*(DATABASE_Table[Typology]<>"")),1),"—")} -> T2 | F15: {=IFERROR(INDEX(_xlfn._xlws.FILTER(DATABASE_Table[Delivery Expected],(DATABASE_Table[Development]=$B15)*(DATABASE_Table[Delivery Expected]<>"")),1),"—")} -> — | G15: =COUNTIF(DATABASE_Table[Development],$B15) -> 55 | H15: {=SUMPRODUCT((DATABASE_Table[Development]=$B15)*(TRIM(DATABASE_Table[Selling Status])="AVAILABLE"))} -> 33 | I15: {=SUMPRODUCT((DATABASE_Table[Development]=$B15)*((TRIM(DATABASE_Table[Selling Status])="RESERVED")+(TRIM(DATABASE_Table[Selling Status])="PRE-RESERVED")))} -> 15 | J15: {=SUMPRODUCT((DATABASE_Table[Development]=$B15)*(LEFT(TRIM(DATABASE_Table[Selling Status]),4)="PSPA"))} -> 7 | K15: {=SUMPRODUCT((DATABASE_Table[Development]=$B15)*(TRIM(DATABASE_Table[Selling Status])="DEED"))} -> 0 | L15: {=SUMPRODUCT((DATABASE_Table[Development]=$B15)*((TRIM(DATABASE_Table[Selling Status])="NOT FOR SALE")+(LEFT(TRIM(DATABASE_Table[Selling Status]),4)="UPON")))} -> 0 | M15: =IFERROR((I15+J15+K15)/(G15-L15),0) -> 0.4 | N15: =SUMIF(DATABASE_Table[Development],$B15,DATABASE_Table[Current Asking price( Total)])/1000000 -> 73.6235 | O15: {=SUMPRODUCT((DATABASE_Table[Development]=$B15)*(TRIM(DATABASE_Table[Selling Status])="DEED SIGNED")*DATABASE_Table[Sell price (RE Asset)])/1000000} -> 0 | X15: {=IFERROR(_xlfn.SWITCH(_xlfn.XLOOKUP($B15,DATABASE_Table[Development],DATABASE_Table[Local],"Center"),"Vilamoura","Vilamoura","Algarve","Algarve","North","North","Center"),"Center")} -> Vilamoura | Y15: {=_xlfn.IFS(G15=0,"—",M15>=0.999,"Sold Out",(I15+J15+K15)=0,"Coming Soon",TRUE,"Active")} -> Active
B16: The Uncommon | C16: =IFERROR(TRIM(_xlfn.XLOOKUP($B16,DATABASE_Table[Development],DATABASE_Table[Selling Status],"—")),"—") -> AVAILABLE | D16: {=IFERROR(INDEX(_xlfn._xlws.FILTER(DATABASE_Table[Location],(DATABASE_Table[Development]=$B16)*(DATABASE_Table[Location]<>"")),1),IFERROR(_xlfn.XLOOKUP($B16,DATABASE_Table[Development],DATABASE_Table[Local],"—"),"—"))} -> Vilamoura, Algarve | E16: {=IFERROR(INDEX(_xlfn._xlws.FILTER(DATABASE_Table[Typology],(DATABASE_Table[Development]=$B16)*(DATABASE_Table[Typology]<>"")),1),"—")} -> T3 | F16: {=IFERROR(INDEX(_xlfn._xlws.FILTER(DATABASE_Table[Delivery Expected],(DATABASE_Table[Development]=$B16)*(DATABASE_Table[Delivery Expected]<>"")),1),"—")} -> — | G16: =COUNTIF(DATABASE_Table[Development],$B16) -> 92 | H16: {=SUMPRODUCT((DATABASE_Table[Development]=$B16)*(TRIM(DATABASE_Table[Selling Status])="AVAILABLE"))} -> 89 | I16: {=SUMPRODUCT((DATABASE_Table[Development]=$B16)*((TRIM(DATABASE_Table[Selling Status])="RESERVED")+(TRIM(DATABASE_Table[Selling Status])="PRE-RESERVED")))} -> 1 | J16: {=SUMPRODUCT((DATABASE_Table[Development]=$B16)*(LEFT(TRIM(DATABASE_Table[Selling Status]),4)="PSPA"))} -> 2 | K16: {=SUMPRODUCT((DATABASE_Table[Development]=$B16)*(TRIM(DATABASE_Table[Selling Status])="DEED"))} -> 0 | L16: {=SUMPRODUCT((DATABASE_Table[Development]=$B16)*((TRIM(DATABASE_Table[Selling Status])="NOT FOR SALE")+(LEFT(TRIM(DATABASE_Table[Selling Status]),4)="UPON")))} -> 0 | M16: =IFERROR((I16+J16+K16)/(G16-L16),0) -> 0.032608696 | N16: =SUMIF(DATABASE_Table[Development],$B16,DATABASE_Table[Current Asking price( Total)])/1000000 -> 125.53 | O16: {=SUMPRODUCT((DATABASE_Table[Development]=$B16)*(TRIM(DATABASE_Table[Selling Status])="DEED SIGNED")*DATABASE_Table[Sell price (RE Asset)])/1000000} -> 0 | X16: {=IFERROR(_xlfn.SWITCH(_xlfn.XLOOKUP($B16,DATABASE_Table[Development],DATABASE_Table[Local],"Center"),"Vilamoura","Vilamoura","Algarve","Algarve","North","North","Center"),"Center")} -> Vilamoura | Y16: {=_xlfn.IFS(G16=0,"—",M16>=0.999,"Sold Out",(I16+J16+K16)=0,"Coming Soon",TRUE,"Active")} -> Active
B17: Rivus | C17: =IFERROR(TRIM(_xlfn.XLOOKUP($B17,DATABASE_Table[Development],DATABASE_Table[Selling Status],"—")),"—") -> AVAILABLE | D17: {=IFERROR(INDEX(_xlfn._xlws.FILTER(DATABASE_Table[Location],(DATABASE_Table[Development]=$B17)*(DATABASE_Table[Location]<>"")),1),IFERROR(_xlfn.XLOOKUP($B17,DATABASE_Table[Development],DATABASE_Table[Local],"—"),"—"))} -> Vilamoura, Algarve | E17: {=IFERROR(INDEX(_xlfn._xlws.FILTER(DATABASE_Table[Typology],(DATABASE_Table[Development]=$B17)*(DATABASE_Table[Typology]<>"")),1),"—")} -> T2 | F17: {=IFERROR(INDEX(_xlfn._xlws.FILTER(DATABASE_Table[Delivery Expected],(DATABASE_Table[Development]=$B17)*(DATABASE_Table[Delivery Expected]<>"")),1),"—")} -> — | G17: =COUNTIF(DATABASE_Table[Development],$B17) -> 39 | H17: {=SUMPRODUCT((DATABASE_Table[Development]=$B17)*(TRIM(DATABASE_Table[Selling Status])="AVAILABLE"))} -> 16 | I17: {=SUMPRODUCT((DATABASE_Table[Development]=$B17)*((TRIM(DATABASE_Table[Selling Status])="RESERVED")+(TRIM(DATABASE_Table[Selling Status])="PRE-RESERVED")))} -> 16 | J17: {=SUMPRODUCT((DATABASE_Table[Development]=$B17)*(LEFT(TRIM(DATABASE_Table[Selling Status]),4)="PSPA"))} -> 7 | K17: {=SUMPRODUCT((DATABASE_Table[Development]=$B17)*(TRIM(DATABASE_Table[Selling Status])="DEED"))} -> 0 | L17: {=SUMPRODUCT((DATABASE_Table[Development]=$B17)*((TRIM(DATABASE_Table[Selling Status])="NOT FOR SALE")+(LEFT(TRIM(DATABASE_Table[Selling Status]),4)="UPON")))} -> 0 | M17: =IFERROR((I17+J17+K17)/(G17-L17),0) -> 0.58974359 | N17: =SUMIF(DATABASE_Table[Development],$B17,DATABASE_Table[Current Asking price( Total)])/1000000 -> 35.56 | O17: {=SUMPRODUCT((DATABASE_Table[Development]=$B17)*(TRIM(DATABASE_Table[Selling Status])="DEED SIGNED")*DATABASE_Table[Sell price (RE Asset)])/1000000} -> 0 | X17: {=IFERROR(_xlfn.SWITCH(_xlfn.XLOOKUP($B17,DATABASE_Table[Development],DATABASE_Table[Local],"Center"),"Vilamoura","Vilamoura","Algarve","Algarve","North","North","Center"),"Center")} -> Vilamoura | Y17: {=_xlfn.IFS(G17=0,"—",M17>=0.999,"Sold Out",(I17+J17+K17)=0,"Coming Soon",TRUE,"Active")} -> Active
B18: Sutaya | C18: =IFERROR(TRIM(_xlfn.XLOOKUP($B18,DATABASE_Table[Development],DATABASE_Table[Selling Status],"—")),"—") -> AVAILABLE | D18: {=IFERROR(INDEX(_xlfn._xlws.FILTER(DATABASE_Table[Location],(DATABASE_Table[Development]=$B18)*(DATABASE_Table[Location]<>"")),1),IFERROR(_xlfn.XLOOKUP($B18,DATABASE_Table[Development],DATABASE_Table[Local],"—"),"—"))} -> Quinta do Lago, Algarve | E18: {=IFERROR(INDEX(_xlfn._xlws.FILTER(DATABASE_Table[Typology],(DATABASE_Table[Development]=$B18)*(DATABASE_Table[Typology]<>"")),1),"—")} -> T3 | F18: {=IFERROR(INDEX(_xlfn._xlws.FILTER(DATABASE_Table[Delivery Expected],(DATABASE_Table[Development]=$B18)*(DATABASE_Table[Delivery Expected]<>"")),1),"—")} -> TBD | G18: =COUNTIF(DATABASE_Table[Development],$B18) -> 16 | H18: {=SUMPRODUCT((DATABASE_Table[Development]=$B18)*(TRIM(DATABASE_Table[Selling Status])="AVAILABLE"))} -> 13 | I18: {=SUMPRODUCT((DATABASE_Table[Development]=$B18)*((TRIM(DATABASE_Table[Selling Status])="RESERVED")+(TRIM(DATABASE_Table[Selling Status])="PRE-RESERVED")))} -> 3 | J18: {=SUMPRODUCT((DATABASE_Table[Development]=$B18)*(LEFT(TRIM(DATABASE_Table[Selling Status]),4)="PSPA"))} -> 0 | K18: {=SUMPRODUCT((DATABASE_Table[Development]=$B18)*(TRIM(DATABASE_Table[Selling Status])="DEED"))} -> 0 | L18: {=SUMPRODUCT((DATABASE_Table[Development]=$B18)*((TRIM(DATABASE_Table[Selling Status])="NOT FOR SALE")+(LEFT(TRIM(DATABASE_Table[Selling Status]),4)="UPON")))} -> 0 | M18: =IFERROR((I18+J18+K18)/(G18-L18),0) -> 0.1875 | N18: =SUMIF(DATABASE_Table[Development],$B18,DATABASE_Table[Current Asking price( Total)])/1000000 -> 94.8 | O18: {=SUMPRODUCT((DATABASE_Table[Development]=$B18)*(TRIM(DATABASE_Table[Selling Status])="DEED SIGNED")*DATABASE_Table[Sell price (RE Asset)])/1000000} -> 0 | X18: {=IFERROR(_xlfn.SWITCH(_xlfn.XLOOKUP($B18,DATABASE_Table[Development],DATABASE_Table[Local],"Center"),"Vilamoura","Vilamoura","Algarve","Algarve","North","North","Center"),"Center")} -> Algarve | Y18: {=_xlfn.IFS(G18=0,"—",M18>=0.999,"Sold Out",(I18+J18+K18)=0,"Coming Soon",TRUE,"Active")} -> Active
B19: Azuya | C19: =IFERROR(TRIM(_xlfn.XLOOKUP($B19,DATABASE_Table[Development],DATABASE_Table[Selling Status],"—")),"—") -> AVAILABLE | D19: {=IFERROR(INDEX(_xlfn._xlws.FILTER(DATABASE_Table[Location],(DATABASE_Table[Development]=$B19)*(DATABASE_Table[Location]<>"")),1),IFERROR(_xlfn.XLOOKUP($B19,DATABASE_Table[Development],DATABASE_Table[Local],"—"),"—"))} -> Ancão, Algarve | E19: {=IFERROR(INDEX(_xlfn._xlws.FILTER(DATABASE_Table[Typology],(DATABASE_Table[Development]=$B19)*(DATABASE_Table[Typology]<>"")),1),"—")} -> T3 Duplex | F19: {=IFERROR(INDEX(_xlfn._xlws.FILTER(DATABASE_Table[Delivery Expected],(DATABASE_Table[Development]=$B19)*(DATABASE_Table[Delivery Expected]<>"")),1),"—")} -> 46752 | G19: =COUNTIF(DATABASE_Table[Development],$B19) -> 16 | H19: {=SUMPRODUCT((DATABASE_Table[Development]=$B19)*(TRIM(DATABASE_Table[Selling Status])="AVAILABLE"))} -> 14 | I19: {=SUMPRODUCT((DATABASE_Table[Development]=$B19)*((TRIM(DATABASE_Table[Selling Status])="RESERVED")+(TRIM(DATABASE_Table[Selling Status])="PRE-RESERVED")))} -> 1 | J19: {=SUMPRODUCT((DATABASE_Table[Development]=$B19)*(LEFT(TRIM(DATABASE_Table[Selling Status]),4)="PSPA"))} -> 1 | K19: {=SUMPRODUCT((DATABASE_Table[Development]=$B19)*(TRIM(DATABASE_Table[Selling Status])="DEED"))} -> 0 | L19: {=SUMPRODUCT((DATABASE_Table[Development]=$B19)*((TRIM(DATABASE_Table[Selling Status])="NOT FOR SALE")+(LEFT(TRIM(DATABASE_Table[Selling Status]),4)="UPON")))} -> 0 | M19: =IFERROR((I19+J19+K19)/(G19-L19),0) -> 0.125 | N19: =SUMIF(DATABASE_Table[Development],$B19,DATABASE_Table[Current Asking price( Total)])/1000000 -> 39.31 | O19: {=SUMPRODUCT((DATABASE_Table[Development]=$B19)*(TRIM(DATABASE_Table[Selling Status])="DEED SIGNED")*DATABASE_Table[Sell price (RE Asset)])/1000000} -> 0 | X19: {=IFERROR(_xlfn.SWITCH(_xlfn.XLOOKUP($B19,DATABASE_Table[Development],DATABASE_Table[Local],"Center"),"Vilamoura","Vilamoura","Algarve","Algarve","North","North","Center"),"Center")} -> Algarve | Y19: {=_xlfn.IFS(G19=0,"—",M19>=0.999,"Sold Out",(I19+J19+K19)=0,"Coming Soon",TRUE,"Active")} -> Active
B20: Palmares | C20: =IFERROR(TRIM(_xlfn.XLOOKUP($B20,DATABASE_Table[Development],DATABASE_Table[Selling Status],"—")),"—") -> AVAILABLE | D20: {=IFERROR(INDEX(_xlfn._xlws.FILTER(DATABASE_Table[Location],(DATABASE_Table[Development]=$B20)*(DATABASE_Table[Location]<>"")),1),IFERROR(_xlfn.XLOOKUP($B20,DATABASE_Table[Development],DATABASE_Table[Local],"—"),"—"))} -> Lagos, Algarve | E20: {=IFERROR(INDEX(_xlfn._xlws.FILTER(DATABASE_Table[Typology],(DATABASE_Table[Development]=$B20)*(DATABASE_Table[Typology]<>"")),1),"—")} -> Plot | F20: {=IFERROR(INDEX(_xlfn._xlws.FILTER(DATABASE_Table[Delivery Expected],(DATABASE_Table[Development]=$B20)*(DATABASE_Table[Delivery Expected]<>"")),1),"—")} -> 46843 | G20: =COUNTIF(DATABASE_Table[Development],$B20) -> 113 | H20: {=SUMPRODUCT((DATABASE_Table[Development]=$B20)*(TRIM(DATABASE_Table[Selling Status])="AVAILABLE"))} -> 71 | I20: {=SUMPRODUCT((DATABASE_Table[Development]=$B20)*((TRIM(DATABASE_Table[Selling Status])="RESERVED")+(TRIM(DATABASE_Table[Selling Status])="PRE-RESERVED")))} -> 6 | J20: {=SUMPRODUCT((DATABASE_Table[Development]=$B20)*(LEFT(TRIM(DATABASE_Table[Selling Status]),4)="PSPA"))} -> 33 | K20: {=SUMPRODUCT((DATABASE_Table[Development]=$B20)*(TRIM(DATABASE_Table[Selling Status])="DEED"))} -> 3 | L20: {=SUMPRODUCT((DATABASE_Table[Development]=$B20)*((TRIM(DATABASE_Table[Selling Status])="NOT FOR SALE")+(LEFT(TRIM(DATABASE_Table[Selling Status]),4)="UPON")))} -> 0 | M20: =IFERROR((I20+J20+K20)/(G20-L20),0) -> 0.37168142 | N20: =SUMIF(DATABASE_Table[Development],$B20,DATABASE_Table[Current Asking price( Total)])/1000000 -> 151.85725 | O20: {=SUMPRODUCT((DATABASE_Table[Development]=$B20)*(TRIM(DATABASE_Table[Selling Status])="DEED SIGNED")*DATABASE_Table[Sell price (RE Asset)])/1000000} -> 0 | X20: {=IFERROR(_xlfn.SWITCH(_xlfn.XLOOKUP($B20,DATABASE_Table[Development],DATABASE_Table[Local],"Center"),"Vilamoura","Vilamoura","Algarve","Algarve","North","North","Center"),"Center")} -> Algarve | Y20: {=_xlfn.IFS(G20=0,"—",M20>=0.999,"Sold Out",(I20+J20+K20)=0,"Coming Soon",TRUE,"Active")} -> Active
B21: Monte Rei | C21: =IFERROR(TRIM(_xlfn.XLOOKUP($B21,DATABASE_Table[Development],DATABASE_Table[Selling Status],"—")),"—") -> AVAILABLE | D21: {=IFERROR(INDEX(_xlfn._xlws.FILTER(DATABASE_Table[Location],(DATABASE_Table[Development]=$B21)*(DATABASE_Table[Location]<>"")),1),IFERROR(_xlfn.XLOOKUP($B21,DATABASE_Table[Development],DATABASE_Table[Local],"—"),"—"))} -> Vila Nova de Cacela, Algarve | E21: {=IFERROR(INDEX(_xlfn._xlws.FILTER(DATABASE_Table[Typology],(DATABASE_Table[Development]=$B21)*(DATABASE_Table[Typology]<>"")),1),"—")} -> T3 | F21: {=IFERROR(INDEX(_xlfn._xlws.FILTER(DATABASE_Table[Delivery Expected],(DATABASE_Table[Development]=$B21)*(DATABASE_Table[Delivery Expected]<>"")),1),"—")} -> TBD | G21: =COUNTIF(DATABASE_Table[Development],$B21) -> 99 | H21: {=SUMPRODUCT((DATABASE_Table[Development]=$B21)*(TRIM(DATABASE_Table[Selling Status])="AVAILABLE"))} -> 95 | I21: {=SUMPRODUCT((DATABASE_Table[Development]=$B21)*((TRIM(DATABASE_Table[Selling Status])="RESERVED")+(TRIM(DATABASE_Table[Selling Status])="PRE-RESERVED")))} -> 4 | J21: {=SUMPRODUCT((DATABASE_Table[Development]=$B21)*(LEFT(TRIM(DATABASE_Table[Selling Status]),4)="PSPA"))} -> 0 | K21: {=SUMPRODUCT((DATABASE_Table[Development]=$B21)*(TRIM(DATABASE_Table[Selling Status])="DEED"))} -> 0 | L21: {=SUMPRODUCT((DATABASE_Table[Development]=$B21)*((TRIM(DATABASE_Table[Selling Status])="NOT FOR SALE")+(LEFT(TRIM(DATABASE_Table[Selling Status]),4)="UPON")))} -> 0 | M21: =IFERROR((I21+J21+K21)/(G21-L21),0) -> 0.04040404 | N21: =SUMIF(DATABASE_Table[Development],$B21,DATABASE_Table[Current Asking price( Total)])/1000000 -> 106.695 | O21: {=SUMPRODUCT((DATABASE_Table[Development]=$B21)*(TRIM(DATABASE_Table[Selling Status])="DEED SIGNED")*DATABASE_Table[Sell price (RE Asset)])/1000000} -> 0 | X21: {=IFERROR(_xlfn.SWITCH(_xlfn.XLOOKUP($B21,DATABASE_Table[Development],DATABASE_Table[Local],"Center"),"Vilamoura","Vilamoura","Algarve","Algarve","North","North","Center"),"Center")} -> Algarve | Y21: {=_xlfn.IFS(G21=0,"—",M21>=0.999,"Sold Out",(I21+J21+K21)=0,"Coming Soon",TRUE,"Active")} -> Active
B22: Aroeira Collections | C22: =IFERROR(TRIM(_xlfn.XLOOKUP($B22,DATABASE_Table[Development],DATABASE_Table[Selling Status],"—")),"—") -> PSPA | D22: {=IFERROR(INDEX(_xlfn._xlws.FILTER(DATABASE_Table[Location],(DATABASE_Table[Development]=$B22)*(DATABASE_Table[Location]<>"")),1),IFERROR(_xlfn.XLOOKUP($B22,DATABASE_Table[Development],DATABASE_Table[Local],"—"),"—"))} -> Herdade da Aroeira, Almada | E22: {=IFERROR(INDEX(_xlfn._xlws.FILTER(DATABASE_Table[Typology],(DATABASE_Table[Development]=$B22)*(DATABASE_Table[Typology]<>"")),1),"—")} -> T2 | F22: {=IFERROR(INDEX(_xlfn._xlws.FILTER(DATABASE_Table[Delivery Expected],(DATABASE_Table[Development]=$B22)*(DATABASE_Table[Delivery Expected]<>"")),1),"—")} -> 47118 | G22: =COUNTIF(DATABASE_Table[Development],$B22) -> 230 | H22: {=SUMPRODUCT((DATABASE_Table[Development]=$B22)*(TRIM(DATABASE_Table[Selling Status])="AVAILABLE"))} -> 153 | I22: {=SUMPRODUCT((DATABASE_Table[Development]=$B22)*((TRIM(DATABASE_Table[Selling Status])="RESERVED")+(TRIM(DATABASE_Table[Selling Status])="PRE-RESERVED")))} -> 25 | J22: {=SUMPRODUCT((DATABASE_Table[Development]=$B22)*(LEFT(TRIM(DATABASE_Table[Selling Status]),4)="PSPA"))} -> 32 | K22: {=SUMPRODUCT((DATABASE_Table[Development]=$B22)*(TRIM(DATABASE_Table[Selling Status])="DEED"))} -> 0 | L22: {=SUMPRODUCT((DATABASE_Table[Development]=$B22)*((TRIM(DATABASE_Table[Selling Status])="NOT FOR SALE")+(LEFT(TRIM(DATABASE_Table[Selling Status]),4)="UPON")))} -> 20 | M22: =IFERROR((I22+J22+K22)/(G22-L22),0) -> 0.27142857 | N22: =SUMIF(DATABASE_Table[Development],$B22,DATABASE_Table[Current Asking price( Total)])/1000000 -> 191.455 | O22: {=SUMPRODUCT((DATABASE_Table[Development]=$B22)*(TRIM(DATABASE_Table[Selling Status])="DEED SIGNED")*DATABASE_Table[Sell price (RE Asset)])/1000000} -> 0 | X22: {=IFERROR(_xlfn.SWITCH(_xlfn.XLOOKUP($B22,DATABASE_Table[Development],DATABASE_Table[Local],"Center"),"Vilamoura","Vilamoura","Algarve","Algarve","North","North","Center"),"Center")} -> Center | Y22: {=_xlfn.IFS(G22=0,"—",M22>=0.999,"Sold Out",(I22+J22+K22)=0,"Coming Soon",TRUE,"Active")} -> Active
B23: Vale Pisão Grand Park | C23: =IFERROR(TRIM(_xlfn.XLOOKUP($B23,DATABASE_Table[Development],DATABASE_Table[Selling Status],"—")),"—") -> AVAILABLE | D23: {=IFERROR(INDEX(_xlfn._xlws.FILTER(DATABASE_Table[Location],(DATABASE_Table[Development]=$B23)*(DATABASE_Table[Location]<>"")),1),IFERROR(_xlfn.XLOOKUP($B23,DATABASE_Table[Development],DATABASE_Table[Local],"—"),"—"))} -> Santo Tirso, Porto | E23: {=IFERROR(INDEX(_xlfn._xlws.FILTER(DATABASE_Table[Typology],(DATABASE_Table[Development]=$B23)*(DATABASE_Table[Typology]<>"")),1),"—")} -> V3 | F23: {=IFERROR(INDEX(_xlfn._xlws.FILTER(DATABASE_Table[Delivery Expected],(DATABASE_Table[Development]=$B23)*(DATABASE_Table[Delivery Expected]<>"")),1),"—")} -> 47208 | G23: =COUNTIF(DATABASE_Table[Development],$B23) -> 45 | H23: {=SUMPRODUCT((DATABASE_Table[Development]=$B23)*(TRIM(DATABASE_Table[Selling Status])="AVAILABLE"))} -> 15 | I23: {=SUMPRODUCT((DATABASE_Table[Development]=$B23)*((TRIM(DATABASE_Table[Selling Status])="RESERVED")+(TRIM(DATABASE_Table[Selling Status])="PRE-RESERVED")))} -> 5 | J23: {=SUMPRODUCT((DATABASE_Table[Development]=$B23)*(LEFT(TRIM(DATABASE_Table[Selling Status]),4)="PSPA"))} -> 0 | K23: {=SUMPRODUCT((DATABASE_Table[Development]=$B23)*(TRIM(DATABASE_Table[Selling Status])="DEED"))} -> 0 | L23: {=SUMPRODUCT((DATABASE_Table[Development]=$B23)*((TRIM(DATABASE_Table[Selling Status])="NOT FOR SALE")+(LEFT(TRIM(DATABASE_Table[Selling Status]),4)="UPON")))} -> 25 | M23: =IFERROR((I23+J23+K23)/(G23-L23),0) -> 0.25 | N23: =SUMIF(DATABASE_Table[Development],$B23,DATABASE_Table[Current Asking price( Total)])/1000000 -> 37.42 | O23: {=SUMPRODUCT((DATABASE_Table[Development]=$B23)*(TRIM(DATABASE_Table[Selling Status])="DEED SIGNED")*DATABASE_Table[Sell price (RE Asset)])/1000000} -> 0 | X23: {=IFERROR(_xlfn.SWITCH(_xlfn.XLOOKUP($B23,DATABASE_Table[Development],DATABASE_Table[Local],"Center"),"Vilamoura","Vilamoura","Algarve","Algarve","North","North","Center"),"Center")} -> North | Y23: {=_xlfn.IFS(G23=0,"—",M23>=0.999,"Sold Out",(I23+J23+K23)=0,"Coming Soon",TRUE,"Active")} -> Active
B24: TOTAL | G24: =SUM(G7:G23) -> 1141 | H24: =SUM(H7:H23) -> 699 | I24: =SUM(I7:I23) -> 86 | J24: =SUM(J7:J23) -> 185 | K24: =SUM(K7:K23) -> 126 | L24: =SUM(L7:L23) -> 45 | M24: =IFERROR((I24+J24+K24)/(G24-L24),0) -> 0.36222628 | N24: =SUM(N7:N23) -> 1314.5806 | O24: =SUM(O7:O23) -> 0
C25: TOTAL UNITS | E25: AVAILABLE | G25: RESERVED | I25: UNDER CONTRACT | K25: DEEDED | M25: % SOLD | N25: GDV (€M)
C26: =G24 -> 1141 | E26: =H24 -> 699 | G26: =I24 -> 86 | I26: =J24 -> 185 | K26: =K24 -> 126 | M26: =M24 -> 0.36222628 | N26: =N24 -> 1314.5806
Q27: Available | R27: =E34 -> 15
Q28: Reserved | R28: =G34 -> 5
C29: PROJECT SPOTLIGHT | Q29: Under Contract | R29: =I34 -> 0
Q30: Deeded | R30: =K34 -> 0
C31: SELECT PROJECT → | E31: Vale Pisão Grand Park | G31: ="📍 "&IFERROR(_xlfn.XLOOKUP($E$31,$B$7:$B$23,$D$7:$D$23),"—")&" · "&IFERROR(_xlfn.XLOOKUP($E$31,$B$7:$B$23,$E$7:$E$23),"—")&" · "&IFERROR(_xlfn.XLOOKUP($E$31,$B$7:$B$23,$X$7:$X$23),"—")&" region · Status: "&IFERROR(_xlfn.XLOOKUP($E$31,$B$7:$B$23,$Y$7:$Y$23),"—")&" · Completion: "&IFERROR(TEXT(_xlfn.XLOOKUP($E$31,$B$7:$B$23,$F$7:$F$23),"dd-mmm-yyyy"),_xlfn.XLOOKUP($E$31,$B$7:$B$23,$F$7:$F$23)) -> 📍 Santo Tirso, Porto · V3 · North region · Status: Active · Completion: 31-mar-yyyy
C33: TOTAL UNITS | E33: AVAILABLE | G33: RESERVED | I33: UNDER CONTRACT | K33: DEEDED | M33: % SOLD | N33: GDV (€M)
C34: =_xlfn.XLOOKUP($E$31,$B$7:$B$23,$G$7:$G$23,0) -> 45 | E34: =_xlfn.XLOOKUP($E$31,$B$7:$B$23,$H$7:$H$23,0) -> 15 | G34: =_xlfn.XLOOKUP($E$31,$B$7:$B$23,$I$7:$I$23,0) -> 5 | I34: =_xlfn.XLOOKUP($E$31,$B$7:$B$23,$J$7:$J$23,0) -> 0 | K34: =_xlfn.XLOOKUP($E$31,$B$7:$B$23,$K$7:$K$23,0) -> 0 | M34: =_xlfn.XLOOKUP($E$31,$B$7:$B$23,$M$7:$M$23,0) -> 0.25 | N34: =_xlfn.XLOOKUP($E$31,$B$7:$B$23,$N$7:$N$23,0) -> 37.42
C36: ANALYTICS

Sheet DATABASE
A1: Commercial ID | B1: Local | C1: Unit PH | D1: Location | E1: Typology | F1: Area Total [sqm] | G1: Storage [sqm] | H1: Parking Lots [#] | I1: Pool [#] | J1: Balconies [sqm] | K1: Garden [sqm] | L1: Patio [sqm] | M1: Terrace [sqm] | N1: Rooftop [sqm] | O1: Interior | P1: Exterior | Q1: Selling Status | R1: Inicial Asking Price (€) (RE Asset) | S1: Inicial Asking Price (€) (Total) | T1: Current Asking price( Total) | U1: Vista membership | V1: FF&E | W1: Current Asking price (RE Asset) | X1: Total Discunt | Y1: Sell price (Total) | Z1: Sell price (RE Asset) | AA1: PSPA Date | AB1: Delivery Expected | AC1: Owner Comercial | AD1: Owner Asset Management | AE1: Website | AF1: Positioning Statement | AG1: Amenities | AH1: Key-Selling Points | AI1: Architecture | AJ1: Development
A2: MR - Linked Villas | B2: Algarve | C2: T | D2: Vila Nova de Cacela, Algarve | E2: T3 | F2: 422.36 | G2: 45.06 | J2: 131.68 | O2: 245.62 | Q2: AVAILABLE | R2: =DATABASE_Table[[#This Row],[Inicial Asking Price (€) (Total)]]-DATABASE_Table[[#This Row],[Vista membership]]-DATABASE_Table[[#This Row],[FF&E]] -> 1160000 | S2: 1160000 | T2: 1160000 | W2: =DATABASE_Table[[#This Row],[Current Asking price( Total)]]-DATABASE_Table[[#This Row],[Vista membership]]-DATABASE_Table[[#This Row],[FF&E]] -> 1160000 | Z2: =DATABASE_Table[[#This Row],[Sell price (Total)]]-DATABASE_Table[[#This Row],[FF&E]]-DATABASE_Table[[#This Row],[Vista membership]] -> 0 | AB2: TBD | AC2: Sandra Viegas | AE2: https://www.monte-rei.com/ | AF2: Monte Rei Golf & Country Club is an ultra-exclusive resort in the Eastern Algarve, combining a Jack Nicklaus Signature golf course, Michelin-star dining, and luxury residences within a serene private estate — offering one of Europe’s most refined golf and lifestyle experiences. | AG2: Golfe 18 buracos, Ténis, Ginásio, Health Center, Piscinas Exteriores, Spa e Concierge, Restaurantes | AH2: O Monte Rei Golf & Country Club é um resort de luxo exclusivo situado em mais de 400 hectares de paisagem intacta no sotavento algarvio, oferecendo a viajantes exigentes e amantes do golfe um refúgio de tranquilidade, sofisticação e privacidade. Com o seu campo de golfe assinatura Jack Nicklaus, gastronomia de excelência, serviço personalizado e um ambiente sereno entre a serra e o Atlântico, o Monte Rei posiciona-se como “o melhor lugar para viver e jogar” — um retiro privado e seguro, longe do ritmo agitado do quotidiano. | AI2: TBD | AJ2: Monte Rei
A3: Aroeira - HOUSES | B3: Center | C3: 01B | D3: Herdade da Aroeira, Almada | E3: T2 | F3: 167 | H3: 1 | M3: 31 | N3: 20 | O3: 116 | Q3: PSPA | R3: =DATABASE_Table[[#This Row],[Inicial Asking Price (€) (Total)]]-DATABASE_Table[[#This Row],[Vista membership]]-DATABASE_Table[[#This Row],[FF&E]] -> 925000 | S3: 925000 | T3: 925000 | V3: 0 | W3: =DATABASE_Table[[#This Row],[Current Asking price( Total)]]-DATABASE_Table[[#This Row],[Vista membership]]-DATABASE_Table[[#This Row],[FF&E]] -> 925000 | X3: 0 | Y3: 925000 | Z3: =DATABASE_Table[[#This Row],[Sell price (Total)]]-DATABASE_Table[[#This Row],[FF&E]]-DATABASE_Table[[#This Row],[Vista membership]] -> 925000 | AA3: 45904 | AB3: 47118 | AC3: João Gameiro | AD3: Miguel Ribeiro | AE3: https://www.aroeiracollections.com/ | AF3: Aroeira Collections by Missoni: Elegance inspired by iconic design, set beside the renowned PGA golf course — where luxury living meets the rhythm of the coast. | AG3: Gym, Spa, Condo Pool, Private Pools, Tennis & Padel Courts, Outdoor Areas, Smart Home Technology, Private Parking, Reception, Missoni Interiors, PGA Golf Course | AH3: Primeiro grande projeto com uma marca de lifestyle/moda em Portugal - Missoni; Localização de excelência dentro da Herdade da Aroeira, a 30' de Lisboa e 10' das melhores praias do país; Design com contributo de arquitetos de renome; Excelente oportunidade de investimento; Junto ao campo de golfe PGA Aroeira; Diversas amenities como: Piscina interior e exterior, campos de tenis e padel, ginásio, spa e restaurante. | AI3: Ana Costa, João Favila, Pedro Domingos | AJ3: Aroeira Collections
A4: Aroeira - HOUSES | B4: Center | C4: 02B | D4: Herdade da Aroeira, Almada | E4: T2 | F4: 194.4 | H4: 1 | M4: 27 | N4: 30 | O4: 137.4 | Q4: PSPA | R4: =DATABASE_Table[[#This Row],[Inicial Asking Price (€) (Total)]]-DATABASE_Table[[#This Row],[Vista membership]]-DATABASE_Table[[#This Row],[FF&E]] -> 1105000 | S4: 1105000 | T4: 1105000 | V4: 0 | W4: =DATABASE_Table[[#This Row],[Current Asking price( Total)]]-DATABASE_Table[[#This Row],[Vista membership]]-DATABASE_Table[[#This Row],[FF&E]] -> 1105000 | X4: 0 | Y4: 1105000 | Z4: =DATABASE_Table[[#This Row],[Sell price (Total)]]-DATABASE_Table[[#This Row],[FF&E]]-DATABASE_Table[[#This Row],[Vista membership]] -> 1105000 | AA4: 45996 | AB4: 47118 | AC4: João Gameiro | AD4: Miguel Ribeiro | AE4: https://www.aroeiracollections.com/ | AF4: Aroeira Collections by Missoni: Elegance inspired by iconic design, set beside the renowned PGA golf course — where luxury living meets the rhythm of the coast. | AG4: Gym, Spa, Condo Pool, Private Pools, Tennis & Padel Courts, Outdoor Areas, Smart Home Technology, Private Parking, Reception, Missoni Interiors, PGA Golf Course | AH4: Primeiro grande projeto com uma marca de lifestyle/moda em Portugal - Missoni; Localização de excelência dentro da Herdade da Aroeira, a 30' de Lisboa e 10' das melhores praias do país; Design com contributo de arquitetos de renome; Excelente oportunidade de investimento; Junto ao campo de golfe PGA Aroeira; Diversas amenities como: Piscina interior e exterior, campos de tenis e padel, ginásio, spa e restaurante. | AI4: Ana Costa, João Favila, Pedro Domingos | AJ4: Aroeira Collections
A5: Aroeira - HOUSES | B5: Center | C5: 03B | D5: Herdade da Aroeira, Almada | E5: T2 | F5: 167 | H5: 1 | M5: 31 | N5: 20 | O5: 116 | Q5: PSPA | R5: =DATABASE_Table[[#This Row],[Inicial Asking Price (€) (Total)]]-DATABASE_Table[[#This Row],[Vista membership]]-DATABASE_Table[[#This Row],[FF&E]] -> 925000 | S5: 925000 | T5: 925000 | V5: 0 | W5: =DATABASE_Table[[#This Row],[Current Asking price( Total)]]-DATABASE_Table[[#This Row],[Vista membership]]-DATABASE_Table[[#This Row],[FF&E]] -> 925000 | X5: 0 | Y5: 925000 | Z5: =DATABASE_Table[[#This Row],[Sell price (Total)]]-DATABASE_Table[[#This Row],[FF&E]]-DATABASE_Table[[#This Row],[Vista membership]] -> 925000 | AA5: 45967 | AB5: 47118 | AC5: João Gameiro | AD5: Miguel Ribeiro | AE5: https://www.aroeiracollections.com/ | AF5: Aroeira Collections by Missoni: Elegance inspired by iconic design, set beside the renowned PGA golf course — where luxury living meets the rhythm of the coast. | AG5: Gym, Spa, Condo Pool, Private Pools, Tennis & Padel Courts, Outdoor Areas, Smart Home Technology, Private Parking, Reception, Missoni Interiors, PGA Golf Course | AH5: Primeiro grande projeto com uma marca de lifestyle/moda em Portugal - Missoni; Localização de excelência dentro da Herdade da Aroeira, a 30' de Lisboa e 10' das melhores praias do país; Design com contributo de arquitetos de renome; Excelente oportunidade de investimento; Junto ao campo de golfe PGA Aroeira; Diversas amenities como: Piscina interior e exterior, campos de tenis e padel, ginásio, spa e restaurante. | AI5: Ana Costa, João Favila, Pedro Domingos | AJ5: Aroeira Collections
A6: Aroeira - HOUSES | B6: Center | C6: 04B | D6: Herdade da Aroeira, Almada | E6: T2 | F6: 167 | H6: 1 | M6: 31 | N6: 20 | O6: 116 | Q6: PSPA | R6: =DATABASE_Table[[#This Row],[Inicial Asking Price (€) (Total)]]-DATABASE_Table[[#This Row],[Vista membership]]-DATABASE_Table[[#This Row],[FF&E]] -> 925000 | S6: 925000 | T6: 925000 | V6: 0 | W6: =DATABASE_Table[[#This Row],[Current Asking price( Total)]]-DATABASE_Table[[#This Row],[Vista membership]]-DATABASE_Table[[#This Row],[FF&E]] -> 925000 | X6: 0 | Y6: 925000 | Z6: =DATABASE_Table[[#This Row],[Sell price (Total)]]-DATABASE_Table[[#This Row],[FF&E]]-DATABASE_Table[[#This Row],[Vista membership]] -> 925000 | AA6: 45968 | AB6: 47118 | AC6: João Gameiro | AD6: Miguel Ribeiro | AE6: https://www.aroeiracollections.com/ | AF6: Aroeira Collections by Missoni: Elegance inspired by iconic design, set beside the renowned PGA golf course — where luxury living meets the rhythm of the coast. | AG6: Gym, Spa, Condo Pool, Private Pools, Tennis & Padel Courts, Outdoor Areas, Smart Home Technology, Private Parking, Reception, Missoni Interiors, PGA Golf Course | AH6: Primeiro grande projeto com uma marca de lifestyle/moda em Portugal - Missoni; Localização de excelência dentro da Herdade da Aroeira, a 30' de Lisboa e 10' das melhores praias do país; Design com contributo de arquitetos de renome; Excelente oportunidade de investimento; Junto ao campo de golfe PGA Aroeira; Diversas amenities como: Piscina interior e exterior, campos de tenis e padel, ginásio, spa e restaurante. | AI6: Ana Costa, João Favila, Pedro Domingos | AJ6: Aroeira Collections
A7: Aroeira - HOTEL APARTMENTS | B7: Center | C7: 143A | D7: Herdade da Aroeira, Almada | E7: 1-BR | F7: 56.5 | H7: 1 | J7: 5 | O7: 51.5 | Q7: RESERVED | R7: =DATABASE_Table[[#This Row],[Inicial Asking Price (€) (Total)]]-DATABASE_Table[[#This Row],[Vista membership]]-DATABASE_Table[[#This Row],[FF&E]] -> 1915000 | S7: 1950000 | T7: 370000 | V7: 35000 | W7: =DATABASE_Table[[#This Row],[Current Asking price( Total)]]-DATABASE_Table[[#This Row],[Vista membership]]-DATABASE_Table[[#This Row],[FF&E]] -> 335000 | X7: 0 | Y7: 370000 | Z7: =DATABASE_Table[[#This Row],[Sell price (Total)]]-DATABASE_Table[[#This Row],[FF&E]]-DATABASE_Table[[#This Row],[Vista membership]] -> 335000 | AA7: 46104 | AB7: 47118 | AC7: João Gameiro | AD7: Miguel Ribeiro | AE7: https://www.aroeiracollections.com/ | AF7: Aroeira Collections by Missoni: Elegance inspired by iconic design, set beside the renowned PGA golf course — where luxury living meets the rhythm of the coast. | AG7: Gym, Spa, Condo Pool, Private Pools, Tennis & Padel Courts, Outdoor Areas, Smart Home Technology, Private Parking, Reception, Missoni Interiors, PGA Golf Course | AH7: Primeiro grande projeto com uma marca de lifestyle/moda em Portugal - Missoni; Localização de excelência dentro da Herdade da Aroeira, a 30' de Lisboa e 10' das melhores praias do país; Design com contributo de arquitetos de renome; Excelente oportunidade de investimento; Junto ao campo de golfe PGA Aroeira; Diversas amenities como: Piscina interior e exterior, campos de tenis e padel, ginásio, spa e restaurante. | AI7: Ana Costa, João Favila, Pedro Domingos | AJ7: Aroeira Collections
A8: Aroeira - HOTEL APARTMENTS | B8: Center | C8: 144A | D8: Herdade da Aroeira, Almada | E8: 1-BR | F8: 56.5 | H8: 1 | J8: 5 | O8: 51.5 | Q8: RESERVED | R8: =DATABASE_Table[[#This Row],[Inicial Asking Price (€) (Total)]]-DATABASE_Table[[#This Row],[Vista membership]]-DATABASE_Table[[#This Row],[FF&E]] -> 1715000 | S8: 1750000 | T8: 370000 | V8: 35000 | W8: =DATABASE_Table[[#This Row],[Current Asking price( Total)]]-DATABASE_Table[[#This Row],[Vista membership]]-DATABASE_Table[[#This Row],[FF&E]] -> 335000 | X8: 0 | Y8: 370000 | Z8: =DATABASE_Table[[#This Row],[Sell price (Total)]]-DATABASE_Table[[#This Row],[FF&E]]-DATABASE_Table[[#This Row],[Vista membership]] -> 335000 | AA8: 46052 | AB8: 47118 | AC8: João Gameiro | AD8: Miguel Ribeiro | AE8: https://www.aroeiracollections.com/ | AF8: Aroeira Collections by Missoni: Elegance inspired by iconic design, set beside the renowned PGA golf course — where luxury living meets the rhythm of the coast. | AG8: Gym, Spa, Condo Pool, Private Pools, Tennis & Padel Courts, Outdoor Areas, Smart Home Technology, Private Parking, Reception, Missoni Interiors, PGA Golf Course | AH8: Primeiro grande projeto com uma marca de lifestyle/moda em Portugal - Missoni; Localização de excelência dentro da Herdade da Aroeira, a 30' de Lisboa e 10' das melhores praias do país; Design com contributo de arquitetos de renome; Excelente oportunidade de investimento; Junto ao campo de golfe PGA Aroeira; Diversas amenities como: Piscina interior e exterior, campos de tenis e padel, ginásio, spa e restaurante. | AI8: Ana Costa, João Favila, Pedro Domingos | AJ8: Aroeira Collections
A9: Aroeira - HOTEL APARTMENTS | B9: Center | C9: 134A | D9: Herdade da Aroeira, Almada | E9: 1-BR | F9: 56.5 | H9: 1 | J9: 5 | O9: 51.5 | Q9: RESERVED | R9: =DATABASE_Table[[#This Row],[Inicial Asking Price (€) (Total)]]-DATABASE_Table[[#This Row],[Vista membership]]-DATABASE_Table[[#This Row],[FF&E]] -> 1715000 | S9: 1750000 | T9: 370000 | V9: 35000 | W9: =DATABASE_Table[[#This Row],[Current Asking price( Total)]]-DATABASE_Table[[#This Row],[Vista membership]]-DATABASE_Table[[#This Row],[FF&E]] -> 335000 | X9: 0.02 | Y9: 362600 | Z9: =DATABASE_Table[[#This Row],[Sell price (Total)]]-DATABASE_Table[[#This Row],[FF&E]]-DATABASE_Table[[#This Row],[Vista membership]] -> 327600 | AA9: 46118 | AB9: 47118 | AC9: João Gameiro | AD9: Miguel Ribeiro | AE9: https://www.aroeiracollections.com/ | AF9: Aroeira Collections by Missoni: Elegance inspired by iconic design, set beside the renowned PGA golf course — where luxury living meets the rhythm of the coast. | AG9: Gym, Spa, Condo Pool, Private Pools, Tennis & Padel Courts, Outdoor Areas, Smart Home Technology, Private Parking, Reception, Missoni Interiors, PGA Golf Course | AH9: Primeiro grande projeto com uma marca de lifestyle/moda em Portugal - Missoni; Localização de excelência dentro da Herdade da Aroeira, a 30' de Lisboa e 10' das melhores praias do país; Design com contributo de arquitetos de renome; Excelente oportunidade de investimento; Junto ao campo de golfe PGA Aroeira; Diversas amenities como: Piscina interior e exterior, campos de tenis e padel, ginásio, spa e restaurante. | AI9: Ana Costa, João Favila, Pedro Domingos | AJ9: Aroeira Collections
A10: Aroeira - HOTEL APARTMENTS | B10: Center | C10: 137A | D10: Herdade da Aroeira, Almada | E10: 1-BR | F10: 56.5 | H10: 1 | J10: 5 | O10: 51.5 | Q10: RESERVED | R10: =DATABASE_Table[[#This Row],[Inicial Asking Price (€) (Total)]]-DATABASE_Table[[#This Row],[Vista membership]]-DATABASE_Table[[#This Row],[FF&E]] -> 1815000 | S10: 1850000 | T10: 370000 | V10: 35000 | W10: =DATABASE_Table[[#This Row],[Current Asking price( Total)]]-DATABASE_Table[[#This Row],[Vista membership]]-DATABASE_Table[[#This Row],[FF&E]] -> 335000 | X10: 0.02 | Y10: 362600 | Z10: =DATABASE_Table[[#This Row],[Sell price (Total)]]-DATABASE_Table[[#This Row],[FF&E]]-DATABASE_Table[[#This Row],[Vista membership]] -> 327600 | AA10: 46118 | AB10: 47118 | AC10: João Gameiro | AD10: Miguel Ribeiro | AE10: https://www.aroeiracollections.com/ | AF10: Aroeira Collections by Missoni: Elegance inspired by iconic design, set beside the renowned PGA golf course — where luxury living meets the rhythm of the coast. | AG10: Gym, Spa, Condo Pool, Private Pools, Tennis & Padel Courts, Outdoor Areas, Smart Home Technology, Private Parking, Reception, Missoni Interiors, PGA Golf Course | AH10: Primeiro grande projeto com uma marca de lifestyle/moda em Portugal - Missoni; Localização de excelência dentro da Herdade da Aroeira, a 30' de Lisboa e 10' das melhores praias do país; Design com contributo de arquitetos de renome; Excelente oportunidade de investimento; Junto ao campo de golfe PGA Aroeira; Diversas amenities como: Piscina interior e exterior, campos de tenis e padel, ginásio, spa e restaurante. | AI10: Ana Costa, João Favila, Pedro Domingos | AJ10: Aroeira Collections
A11: Aroeira - HOTEL APARTMENTS | B11: Center | C11: 236A | D11: Herdade da Aroeira, Almada | E11: 1-BR | F11: 56.5 | H11: 1 | J11: 5 | O11: 51.5 | Q11: PRE-RESERVED | R11: =DATABASE_Table[[#This Row],[Inicial Asking Price (€) (Total)]]-DATABASE_Table[[#This Row],[Vista membership]]-DATABASE_Table[[#This Row],[FF&E]] -> 1915000 | S11: 1950000 | T11: 390000 | V11: 35000 | W11: =DATABASE_Table[[#This Row],[Current Asking price( Total)]]-DATABASE_Table[[#This Row],[Vista membership]]-DATABASE_Table[[#This Row],[FF&E]] -> 355000 | X11: 0 | Y11: 390000 | Z11: =DATABASE_Table[[#This Row],[Sell price (Total)]]-DATABASE_Table[[#This Row],[FF&E]]-DATABASE_Table[[#This Row],[Vista membership]] -> 355000 | AA11: 46142 | AB11: 47118 | AC11: João Gameiro | AD11: Miguel Ribeiro | AE11: https://www.aroeiracollections.com/ | AF11: Aroeira Collections by Missoni: Elegance inspired by iconic design, set beside the renowned PGA golf course — where luxury living meets the rhythm of the coast. | AG11: Gym, Spa, Condo Pool, Private Pools, Tennis & Padel Courts, Outdoor Areas, Smart Home Technology, Private Parking, Reception, Missoni Interiors, PGA Golf Course | AH11: Primeiro grande projeto com uma marca de lifestyle/moda em Portugal - Missoni; Localização de excelência dentro da Herdade da Aroeira, a 30' de Lisboa e 10' das melhores praias do país; Design com contributo de arquitetos de renome; Excelente oportunidade de investimento; Junto ao campo de golfe PGA Aroeira; Diversas amenities como: Piscina interior e exterior, campos de tenis e padel, ginásio, spa e restaurante. | AI11: Ana Costa, João Favila, Pedro Domingos | AJ11: Aroeira Collections
A12: Aroeira - HOTEL APARTMENTS | B12: Center | C12: 139A | D12: Herdade da Aroeira, Almada | E12: 1-BR | F12: 60.2 | H12: 1 | J12: 3.9 | O12: 56.3 | Q12: RESERVED | R12: =DATABASE_Table[[#This Row],[Inicial Asking Price (€) (Total)]]-DATABASE_Table[[#This Row],[Vista membership]]-DATABASE_Table[[#This Row],[FF&E]] -> 2065000 | S12: 2100000 | T12: 390000 | V12: 35000 | W12: =DATABASE_Table[[#This Row],[Current Asking price( Total)]]-DATABASE_Table[[#This Row],[Vista membership]]-DATABASE_Table[[#This Row],[FF&E]] -> 355000 | X12: 0 | Y12: 390000 | Z12: =DATABASE_Table[[#This Row],[Sell price (Total)]]-DATABASE_Table[[#This Row],[FF&E]]-DATABASE_Table[[#This Row],[Vista membership]] -> 355000 | AA12: 46098 | AB12: 47118 | AC12: João Gameiro | AD12: Miguel Ribeiro | AE12: https://www.aroeiracollections.com/ | AF12: Aroeira Collections by Missoni: Elegance inspired by iconic design, set beside the renowned PGA golf course — where luxury living meets the rhythm of the coast. | AG12: Gym, Spa, Condo Pool, Private Pools, Tennis & Padel Courts, Outdoor Areas, Smart Home Technology, Private Parking, Reception, Missoni Interiors, PGA Golf Course | AH12: Primeiro grande projeto com uma marca de lifestyle/moda em Portugal - Missoni; Localização de excelência dentro da Herdade da Aroeira, a 30' de Lisboa e 10' das melhores praias do país; Design com contributo de arquitetos de renome; Excelente oportunidade de investimento; Junto ao campo de golfe PGA Aroeira; Diversas amenities como: Piscina interior e exterior, campos de tenis e padel, ginásio, spa e restaurante. | AI12: Ana Costa, João Favila, Pedro Domingos | AJ12: Aroeira Collections
A13: Aroeira - HOTEL APARTMENTS | B13: Center | C13: 140A | D13: Herdade da Aroeira, Almada | E13: 1-BR | F13: 60.2 | H13: 1 | J13: 3.9 | O13: 56.3 | Q13: RESERVED | R13: =DATABASE_Table[[#This Row],[Inicial Asking Price (€) (Total)]]-DATABASE_Table[[#This Row],[Vista membership]]-DATABASE_Table[[#This Row],[FF&E]] -> 2865000 | S13: 2900000 | T13: 390000 | V13: 35000 | W13: =DATABASE_Table[[#This Row],[Current Asking price( Total)]]-DATABASE_Table[[#This Row],[Vista membership]]-DATABASE_Table[[#This Row],[FF&E]] -> 355000 | X13: 0 | Y13: 390000 | Z13: =DATABASE_Table[[#This Row],[Sell price (Total)]]-DATABASE_Table[[#This Row],[FF&E]]-DATABASE_Table[[#This Row],[Vista membership]] -> 355000 | AA13: 46085 | AB13: 47118 | AC13: João Gameiro | AD13: Miguel Ribeiro | AE13: https://www.aroeiracollections.com/ | AF13: Aroeira Collections by Missoni: Elegance inspired by iconic design, set beside the renowned PGA golf course — where luxury living meets the rhythm of the coast. | AG13: Gym, Spa, Condo Pool, Private Pools, Tennis & Padel Courts, Outdoor Areas, Smart Home Technology, Private Parking, Reception, Missoni Interiors, PGA Golf Course | AH13: Primeiro grande projeto com uma marca de lifestyle/moda em Portugal - Missoni; Localização de excelência dentro da Herdade da Aroeira, a 30' de Lisboa e 10' das melhores praias do país; Design com contributo de arquitetos de renome; Excelente oportunidade de investimento; Junto ao campo de golfe PGA Aroeira; Diversas amenities como: Piscina interior e exterior, campos de tenis e padel, ginásio, spa e restaurante. | AI13: Ana Costa, João Favila, Pedro Domingos | AJ13: Aroeira Collections
